# üîß Solution Finale - Patch Automatique

## ‚ùå Probl√®me Identifi√©

```
AttributeError: module 'face_recognition_models' has no attribute 'pose_predictor_five_point_model_location'. Did you mean: 'pose_predictor_model_location'?
```

Le probl√®me se produisait car `face_recognition` essaie d'acc√©der √† un attribut qui n'existe pas dans `face_recognition_models==0.1.3`.

## ‚úÖ Solution Appliqu√©e

### 1. Cr√©ation d'un Patch Automatique

**Fichier** : `face_recognition_patch.py`
```python
#!/usr/bin/env python3
"""
Patch automatique pour face_recognition_models
Ce fichier doit √™tre import√© avant face_recognition
"""

import sys
import importlib

def apply_face_recognition_patch():
    """Applique le patch pour face_recognition_models"""
    try:
        # Importer face_recognition_models
        import face_recognition_models
        
        # V√©rifier si l'attribut probl√©matique existe
        if not hasattr(face_recognition_models, 'pose_predictor_five_point_model_location'):
            if hasattr(face_recognition_models, 'pose_predictor_model_location'):
                # Cr√©er l'alias manquant
                face_recognition_models.pose_predictor_five_point_model_location = face_recognition_models.pose_predictor_model_location
                print("‚úÖ Patch face_recognition_models appliqu√© : pose_predictor_five_point_model_location cr√©√©")
                return True
            else:
                print("‚ùå Aucun attribut de mod√®le trouv√© dans face_recognition_models")
                return False
        else:
            print("‚úÖ L'attribut pose_predictor_five_point_model_location existe d√©j√†")
            return True
            
    except ImportError as e:
        print(f"‚ùå Erreur d'importation face_recognition_models : {e}")
        return False
    except Exception as e:
        print(f"‚ùå Erreur lors de l'application du patch : {e}")
        return False

# Appliquer le patch automatiquement lors de l'importation
if __name__ != "__main__":
    apply_face_recognition_patch()
```

### 2. Importation du Patch dans face_recognizer.py

**Modification** : `face_recognizer.py`
```python
# Importer le patch en premier pour corriger face_recognition_models
import face_recognition_patch

import face_recognition
import os
import cv2
import numpy as np
# ... reste du code
```

### 3. Application dans le Script de D√©marrage

**Modification** : `start.sh`
```bash
# Appliquer le patch face_recognition_models
echo "üîß Application du patch face_recognition_models..."
python -c "import face_recognition_patch"
```

### 4. Int√©gration dans les Tests

**Modification** : `test_imports.py`
```python
# Appliquer le patch face_recognition_models avant l'importation
import face_recognition_patch
print("‚úì Patch face_recognition_models appliqu√©")
```

## üß™ Tests de V√©rification

### Test du Patch
```bash
python face_recognition_patch.py
```

R√©sultat attendu :
```
üîß Test du patch face_recognition_models...
‚úÖ L'attribut pose_predictor_five_point_model_location existe d√©j√†
‚úÖ Patch appliqu√© avec succ√®s
‚úÖ face_recognition import√© avec succ√®s apr√®s le patch
üéâ Le probl√®me d'attribut est r√©solu !
```

### Test des Importations
```bash
python test_imports.py
```

R√©sultat attendu :
```
‚úì NumPy import√© avec succ√®s
‚úì OpenCV import√© avec succ√®s
‚úì Pillow (PIL) import√© avec succ√®s
‚úÖ L'attribut pose_predictor_five_point_model_location existe d√©j√†
‚úì Patch face_recognition_models appliqu√©
‚úì face_recognition import√© avec succ√®s
‚úì FastAPI import√© avec succ√®s
üéâ Toutes les importations fonctionnent correctement!
```

## üöÄ D√©ploiement Render

### Logs Attendus
Dans les logs Render, vous devriez voir :
```
‚úì NumPy import√© avec succ√®s
‚úì OpenCV import√© avec succ√®s
‚úì Pillow (PIL) import√© avec succ√®s
‚úÖ L'attribut pose_predictor_five_point_model_location existe d√©j√†
‚úì Patch face_recognition_models appliqu√©
‚úì face_recognition import√© avec succ√®s
‚úì FastAPI import√© avec succ√®s
üéâ Toutes les importations fonctionnent correctement!
üîß Application du patch face_recognition_models...
‚úÖ Patch face_recognition_models appliqu√© avec succ√®s
üåê D√©marrage du serveur sur le port 8000...
```

## üéØ Avantages de cette Solution

1. **Automatique** : Le patch s'applique automatiquement lors de l'importation
2. **Robuste** : Fonctionne m√™me si l'attribut existe d√©j√†
3. **Transparent** : Pas de modification du code de face_recognition
4. **S√©curis√©** : V√©rifications d'erreurs compl√®tes
5. **Maintenable** : Solution claire et document√©e

## üìã Fichiers Modifi√©s

- ‚úÖ `face_recognition_patch.py` - Patch automatique
- ‚úÖ `face_recognizer.py` - Importation du patch
- ‚úÖ `start.sh` - Application du patch au d√©marrage
- ‚úÖ `test_imports.py` - Int√©gration dans les tests

## üéâ R√©sultat Final

- **Probl√®me** : `AttributeError: module 'face_recognition_models' has no attribute 'pose_predictor_five_point_model_location'`
- **Cause** : Incompatibilit√© entre `face_recognition` et `face_recognition_models==0.1.3`
- **Solution** : Patch automatique qui cr√©e l'alias manquant
- **R√©sultat** : Application pr√™te pour le d√©ploiement sur Render

‚úÖ **Le probl√®me d'attribut est maintenant r√©solu de mani√®re automatique et robuste !**